<?xml version="1.0"?>
<robot xmlns:xacro="http://www.ros.org/wiki/xacro" >

    <joint name="arka_sag_sarhos_teker_joint" type="continuous">
        <origin xyz="0 -0.0005 -0.05" rpy="0 0 0"/>
        <parent link="arka_sag_sarhos_teker_plakasi_link"/>
        <child link="arka_sag_sarhos_teker_link"/> 
        <axis xyz="0 1 0"/> 
    </joint>

    <link name="arka_sag_sarhos_teker_link">
        <visual>
            <origin xyz="0 -0.025 0" rpy="0 0 0"/>
            <geometry> 
                <mesh filename="package://prototype_vehicle/mesh/SarhosTekerler.stl" scale="0.001 0.001 0.001"/> 
            </geometry>
            <material name="Green">
                <color rgba="0 1 0 1"/>
            </material>
        </visual>
        <collision>
            <origin xyz="0 -0.025 0" rpy="0 0 0"/>
            <geometry> 
                <mesh filename="package://prototype_vehicle/mesh/SarhosTekerler.stl" scale="0.001 0.001 0.001"/> 
            </geometry>
        </collision>
        <inertial>
            <origin xyz="0 0 0" rpy="0 0 0"/>
            <mass value="0.282" />
            <inertia ixx="0.0"  ixy="0.0"  ixz="0.0" 
                     iyx="0.0"  iyy="0.0"  iyz="0.0" 
                     izx="0.0"  izy="0.0"  izz="0.0" />
        </inertial>
    </link> 

    <gazebo reference="arka_sag_sarhos_teker_link">
        <material>Gazebo/Green</material>
        <mu1 value="0"/>
        <mu2 value="0"/>
        <kp value="10000000.0"/>
        <kd value="1.0"/>
        <minDepth>0.01</minDepth>
    </gazebo>

    <transmission name="arka_sag_sarhos_teker_transmission">
        <type>transmission_interface/SimpleTransmission</type>
        <joint name="arka_sag_sarhos_teker_joint">
            <hardwareInterface>hardware_interface/VelocityJointInterface</hardwareInterface>
        </joint>
        <actuator name="arka_sag_sarhos_teker_joint_motor">
            <hardwareInterface>hardware_interface/VelocityJointInterface</hardwareInterface>
            <mechanicalReduction>1</mechanicalReduction>
        </actuator>
    </transmission>

</robot>