<?xml version="1.0"?>
<robot xmlns:xacro="http://www.ros.org/wiki/xacro" >

    <joint name="arka_sag_sarhos_teker_plakasi_joint" type="continuous">
        <origin xyz="-0.325 -0.178 -0.097" rpy="0 0 0"/>
        <parent link="base_link"/>
        <child link="arka_sag_sarhos_teker_plakasi_link"/> 
        <axis xyz="0 0 1"/> 
        <dynamics damping="0.01" friction="0.0"/>
    </joint>

    <link name="arka_sag_sarhos_teker_plakasi_link">
        <visual>
            <origin xyz="0.00007437 -0.053 -0.041" rpy="0 0 0"/>
            <geometry> 
                <mesh filename="package://prototype_vehicle/mesh/SarhosTekerPlakasi.stl" scale="0.001 0.001 0.001"/> 
            </geometry>
            <material name="Green">
                <color rgba="0 1 0 1"/>
            </material>
        </visual>
        <collision>
            <origin xyz="0.00007437 -0.053 -0.041" rpy="0 0 0"/>
            <geometry> 
                <mesh filename="package://prototype_vehicle/mesh/SarhosTekerPlakasi.stl" scale="0.001 0.001 0.001"/> 
            </geometry>
        </collision>
        <inertial>
            <origin xyz="0 0 0" rpy="0 0 0"/>
            <mass value="0.021" />
            <inertia ixx="0.000009753"  ixy="0.0"  ixz="-0.00000001956" 
                     iyx="0.0"  iyy="0.00001319"  iyz="0.0" 
                     izx="0.00000001956"  izy="0.0"  izz="0.000003529" />
        </inertial>
    </link> 

    <gazebo reference="arka_sag_sarhos_teker_plakasi_link">
        <material>Gazebo/Green</material>
        <mu1 value="0"/>
        <mu2 value="0"/>
        <kp value="10000000.0"/>
        <kd value="1.0"/>
        <minDepth>0.01</minDepth>
    </gazebo>

    <transmission name="arka_sag_sarhos_teker_plakasi_transmission">
        <type>transmission_interface/SimpleTransmission</type>
        <joint name="arka_sag_sarhos_teker_plakasi_joint">
            <hardwareInterface>hardware_interface/VelocityJointInterface</hardwareInterface>
        </joint>
        <actuator name="arka_sag_sarhos_teker_plakasi_joint_motor">
            <hardwareInterface>hardware_interface/VelocityJointInterface</hardwareInterface>
            <mechanicalReduction>1</mechanicalReduction>
        </actuator>
    </transmission>

</robot>