<?xml version="1.0"?>
<robot xmlns:xacro="http://www.ros.org/wiki/xacro">

    <joint name="left_wheel_joint" type="continuous">
        <origin xyz="0 0.235 -0.105" rpy="-1.5708 0 0" />
        <parent link="base_link" />
        <child link="left_wheel_link" />
        <axis xyz="0 0 1" />
        <limit effort="100" velocity="20.0" />
    </joint>

    <link name="left_wheel_link">
        <visual>
            <origin xyz="0.042 -0.065 -0.188" rpy="0 0 0" />
            <geometry>
                <mesh filename="package://prototype_vehicle_mini/mesh/ReduktorluTeker.stl" scale="0.001 0.001 0.001" />
            </geometry>
            <material name="Red">
                <color rgba="1 0 0 1" />
            </material>
        </visual>
        <collision>
            <origin xyz="0.042 -0.065 -0.188" rpy="0 0 0" />
            <geometry>
                <mesh filename="package://prototype_vehicle_mini/mesh/ReduktorluTeker.stl" scale="0.001 0.001 0.001" />
            </geometry>
        </collision>
        <inertial>
            <origin xyz="0 0 0" rpy="0 0 0" />
            <mass value="10" />
            <inertia ixx="0.021" ixy="0.0" ixz="0.0" iyx="0.0" iyy="0.021" iyz="0.000001185" izx="0.0" izy="0.000001185" izz="0.032" />
        </inertial>
    </link>

</robot>